I'm sorry, but an uncaught exception occurred.

While running game code:
  File "game/script.rpy", line 27, in script
    n "4"
Exception: Sayer 'n' is not defined.

-- Full Traceback ------------------------------------------------------------

Full traceback:
  File "game/script.rpy", line 27, in script
    n "4"
  File "renpy/ast.py", line 681, in execute
    who = eval_who(self.who, self.who_fast)
  File "renpy/ast.py", line 574, in eval_who
    raise Exception("Sayer '%s' is not defined." % who)
Exception: Sayer 'n' is not defined.

Windows-10-10.0.22621
Ren'Py 7.4.8.1895
Blue_Gem 1.0
Thu May 25 15:59:39 2023
